Using license file /home/weit/gurobi.lic
Academic license - for non-commercial use only
Traceback (most recent call last):
  File "/home/weit/anaconda3/envs/cc-env/lib/python3.7/runpy.py", line 193, in _run_module_as_main
    "__main__", mod_spec)
  File "/home/weit/anaconda3/envs/cc-env/lib/python3.7/runpy.py", line 85, in _run_code
    exec(code, run_globals)
  File "/home/weit/circuit_cutting/large_on_small/generator.py", line 19, in <module>
    ground_truth = evaluate_circ(circ=circ,backend='statevector_simulator',evaluator_info=None,force_prob=True)
  File "/home/weit/circuit_cutting/utils/helper_fun.py", line 219, in evaluate_circ
    result = job.result()
  File "/home/weit/anaconda3/envs/cc-env/lib/python3.7/site-packages/qiskit/providers/aer/aerjob.py", line 41, in _wrapper
    return func(self, *args, **kwargs)
  File "/home/weit/anaconda3/envs/cc-env/lib/python3.7/site-packages/qiskit/providers/aer/aerjob.py", line 94, in result
    return self._future.result(timeout=timeout)
  File "/home/weit/anaconda3/envs/cc-env/lib/python3.7/concurrent/futures/_base.py", line 435, in result
    return self.__get_result()
  File "/home/weit/anaconda3/envs/cc-env/lib/python3.7/concurrent/futures/_base.py", line 384, in __get_result
    raise self._exception
  File "/home/weit/anaconda3/envs/cc-env/lib/python3.7/concurrent/futures/thread.py", line 57, in run
    result = self.fn(*self.args, **self.kwargs)
  File "/home/weit/anaconda3/envs/cc-env/lib/python3.7/site-packages/qiskit/providers/aer/backends/aerbackend.py", line 134, in _run_job
    output = json.loads(self._controller(qobj_str).decode('UTF-8'))
  File "/home/weit/anaconda3/envs/cc-env/lib/python3.7/json/__init__.py", line 348, in loads
    return _default_decoder.decode(s)
  File "/home/weit/anaconda3/envs/cc-env/lib/python3.7/json/decoder.py", line 337, in decode
    obj, end = self.raw_decode(s, idx=_w(s, 0).end())
  File "/home/weit/anaconda3/envs/cc-env/lib/python3.7/json/decoder.py", line 353, in raw_decode
    obj, end = self.scan_once(s, idx)
MemoryError
case (14, 20)
MIP searcher clusters: [11.0, 13.0]
4 cuts --> [11, 13], searcher time = 0.958592414855957
--------------------------------------------------
case (15, 22)
MIP searcher clusters: [11.0, 13.0]
2 cuts --> [11, 13], searcher time = 0.45119333267211914
--------------------------------------------------
INTEL MKL ERROR: /home/weit/anaconda3/envs/cc-env/lib/python3.7/site-packages/mkl/../../../libmkl_core.so: cannot make segment writable for relocation: Cannot allocate memory.
Intel MKL FATAL ERROR: Cannot load libmkl_core.so.
Traceback (most recent call last):
  File "/home/weit/anaconda3/envs/cc-env/lib/python3.7/runpy.py", line 193, in _run_module_as_main
  File "/home/weit/anaconda3/envs/cc-env/lib/python3.7/runpy.py", line 85, in _run_code
  File "/home/weit/circuit_cutting/utils/evaluator.py", line 1, in <module>
  File "/home/weit/anaconda3/envs/cc-env/lib/python3.7/site-packages/qiskit/__init__.py", line 30, in <module>
  File "/home/weit/anaconda3/envs/cc-env/lib/python3.7/site-packages/qiskit/circuit/__init__.py", line 60, in <module>
  File "/home/weit/anaconda3/envs/cc-env/lib/python3.7/site-packages/qiskit/circuit/gate.py", line 18, in <module>
  File "/home/weit/anaconda3/envs/cc-env/lib/python3.7/site-packages/scipy/__init__.py", line 79, in <module>
  File "/home/weit/anaconda3/envs/cc-env/lib/python3.7/site-packages/scipy/_lib/deprecation.py", line 16, in wrap
  File "/home/weit/anaconda3/envs/cc-env/lib/python3.7/functools.py", line 54, in update_wrapper
MemoryError
Traceback (most recent call last):
  File "/home/weit/anaconda3/envs/cc-env/lib/python3.7/runpy.py", line 193, in _run_module_as_main
  File "/home/weit/anaconda3/envs/cc-env/lib/python3.7/runpy.py", line 85, in _run_code
  File "/home/weit/circuit_cutting/utils/evaluator.py", line 1, in <module>
  File "/home/weit/anaconda3/envs/cc-env/lib/python3.7/site-packages/qiskit/__init__.py", line 30, in <module>
  File "/home/weit/anaconda3/envs/cc-env/lib/python3.7/site-packages/qiskit/circuit/__init__.py", line 57, in <module>
  File "/home/weit/anaconda3/envs/cc-env/lib/python3.7/site-packages/qiskit/circuit/quantumcircuit.py", line 22, in <module>
  File "/home/weit/anaconda3/envs/cc-env/lib/python3.7/site-packages/qiskit/circuit/instruction.py", line 45, in <module>
  File "/home/weit/anaconda3/envs/cc-env/lib/python3.7/site-packages/qiskit/qobj/__init__.py", line 73, in <module>
  File "/home/weit/anaconda3/envs/cc-env/lib/python3.7/site-packages/qiskit/qobj/models/base.py", line 17, in <module>
  File "/home/weit/anaconda3/envs/cc-env/lib/python3.7/site-packages/marshmallow/__init__.py", line 1, in <module>
  File "/home/weit/anaconda3/envs/cc-env/lib/python3.7/site-packages/marshmallow/schema.py", line 11, in <module>
  File "<frozen importlib._bootstrap>", line 983, in _find_and_load
  File "<frozen importlib._bootstrap>", line 967, in _find_and_load_unlocked
  File "<frozen importlib._bootstrap>", line 677, in _load_unlocked
  File "<frozen importlib._bootstrap_external>", line 724, in exec_module
  File "<frozen importlib._bootstrap_external>", line 857, in get_code
  File "<frozen importlib._bootstrap_external>", line 525, in _compile_bytecode
MemoryError
Error in atexit._run_exitfuncs:
Traceback (most recent call last):
  File "/home/weit/anaconda3/envs/cc-env/lib/python3.7/logging/__init__.py", line 2033, in shutdown
  File "/home/weit/anaconda3/envs/cc-env/lib/python3.7/logging/__init__.py", line 1009, in flush
MemoryError
Traceback (most recent call last):
  File "/home/weit/anaconda3/envs/cc-env/lib/python3.7/runpy.py", line 193, in _run_module_as_main
  File "/home/weit/anaconda3/envs/cc-env/lib/python3.7/runpy.py", line 85, in _run_code
  File "/home/weit/circuit_cutting/utils/evaluator.py", line 1, in <module>
  File "/home/weit/anaconda3/envs/cc-env/lib/python3.7/site-packages/qiskit/__init__.py", line 30, in <module>
  File "/home/weit/anaconda3/envs/cc-env/lib/python3.7/site-packages/qiskit/circuit/__init__.py", line 57, in <module>
  File "/home/weit/anaconda3/envs/cc-env/lib/python3.7/site-packages/qiskit/circuit/quantumcircuit.py", line 22, in <module>
  File "/home/weit/anaconda3/envs/cc-env/lib/python3.7/site-packages/qiskit/circuit/instruction.py", line 45, in <module>
  File "/home/weit/anaconda3/envs/cc-env/lib/python3.7/site-packages/qiskit/qobj/__init__.py", line 76, in <module>
  File "/home/weit/anaconda3/envs/cc-env/lib/python3.7/site-packages/qiskit/qobj/models/pulse.py", line 19, in <module>
  File "/home/weit/anaconda3/envs/cc-env/lib/python3.7/site-packages/qiskit/qobj/utils.py", line 19, in <module>
  File "/home/weit/anaconda3/envs/cc-env/lib/python3.7/site-packages/qiskit/validation/jsonschema/__init__.py", line 18, in <module>
  File "/home/weit/anaconda3/envs/cc-env/lib/python3.7/site-packages/qiskit/validation/jsonschema/schema_validation.py", line 20, in <module>
  File "/home/weit/anaconda3/envs/cc-env/lib/python3.7/site-packages/jsonschema/__init__.py", line 11, in <module>
  File "/home/weit/anaconda3/envs/cc-env/lib/python3.7/site-packages/jsonschema/exceptions.py", line 11, in <module>
  File "/home/weit/anaconda3/envs/cc-env/lib/python3.7/site-packages/jsonschema/_utils.py", line 6, in <module>
  File "/home/weit/anaconda3/envs/cc-env/lib/python3.7/site-packages/jsonschema/compat.py", line 25, in <module>
  File "<frozen importlib._bootstrap>", line 983, in _find_and_load
  File "<frozen importlib._bootstrap>", line 967, in _find_and_load_unlocked
  File "<frozen importlib._bootstrap>", line 677, in _load_unlocked
  File "<frozen importlib._bootstrap_external>", line 724, in exec_module
  File "<frozen importlib._bootstrap_external>", line 857, in get_code
  File "<frozen importlib._bootstrap_external>", line 525, in _compile_bytecode
MemoryError
Error in atexit._run_exitfuncs:
Traceback (most recent call last):
  File "/home/weit/anaconda3/envs/cc-env/lib/python3.7/logging/__init__.py", line 2033, in shutdown
  File "/home/weit/anaconda3/envs/cc-env/lib/python3.7/logging/__init__.py", line 1009, in flush
MemoryError
Traceback (most recent call last):
  File "/home/weit/anaconda3/envs/cc-env/lib/python3.7/runpy.py", line 193, in _run_module_as_main
  File "/home/weit/anaconda3/envs/cc-env/lib/python3.7/runpy.py", line 85, in _run_code
  File "/home/weit/circuit_cutting/utils/evaluator.py", line 1, in <module>
  File "/home/weit/anaconda3/envs/cc-env/lib/python3.7/site-packages/qiskit/__init__.py", line 30, in <module>
  File "/home/weit/anaconda3/envs/cc-env/lib/python3.7/site-packages/qiskit/circuit/__init__.py", line 57, in <module>
  File "/home/weit/anaconda3/envs/cc-env/lib/python3.7/site-packages/qiskit/circuit/quantumcircuit.py", line 22, in <module>
  File "/home/weit/anaconda3/envs/cc-env/lib/python3.7/site-packages/qiskit/circuit/instruction.py", line 45, in <module>
  File "/home/weit/anaconda3/envs/cc-env/lib/python3.7/site-packages/qiskit/qobj/__init__.py", line 76, in <module>
  File "/home/weit/anaconda3/envs/cc-env/lib/python3.7/site-packages/qiskit/qobj/models/pulse.py", line 19, in <module>
  File "/home/weit/anaconda3/envs/cc-env/lib/python3.7/site-packages/qiskit/qobj/utils.py", line 19, in <module>
  File "/home/weit/anaconda3/envs/cc-env/lib/python3.7/site-packages/qiskit/validation/jsonschema/__init__.py", line 18, in <module>
  File "/home/weit/anaconda3/envs/cc-env/lib/python3.7/site-packages/qiskit/validation/jsonschema/schema_validation.py", line 19, in <module>
  File "<frozen importlib._bootstrap>", line 983, in _find_and_load
  File "<frozen importlib._bootstrap>", line 967, in _find_and_load_unlocked
  File "<frozen importlib._bootstrap>", line 677, in _load_unlocked
  File "<frozen importlib._bootstrap_external>", line 724, in exec_module
  File "<frozen importlib._bootstrap_external>", line 818, in get_code
  File "<frozen importlib._bootstrap_external>", line 917, in get_data
MemoryError
Error in atexit._run_exitfuncs:
Traceback (most recent call last):
  File "/home/weit/anaconda3/envs/cc-env/lib/python3.7/logging/__init__.py", line 2033, in shutdown
  File "/home/weit/anaconda3/envs/cc-env/lib/python3.7/logging/__init__.py", line 1009, in flush
MemoryError
Fatal Python error: Cannot recover from MemoryErrors while normalizing exceptions.

Current thread 0x00007f56c5928740 (most recent call first):
  File "<frozen importlib._bootstrap>", line 604 in _module_repr_from_spec
  File "<frozen importlib._bootstrap>", line 286 in _module_repr
MemoryError

During handling of the above exception, another exception occurred:

MemoryError

During handling of the above exception, another exception occurred:

MemoryError

During handling of the above exception, another exception occurred:

MemoryError

During handling of the above exception, another exception occurred:



During handling of the above exception, another exception occurred:

MemoryError

During handling of the above exception, another exception occurred:

MemoryError

During handling of the above exception, another exception occurred:

MemoryError

During handling of the above exception, another exception occurred:

MemoryError

During handling of the above exception, another exception occurred:



During handling of the above exception, another exception occurred:

MemoryError

During handling of the above exception, another exception occurred:

MemoryError

During handling of the above exception, another exception occurred:

MemoryError

During handling of the above exception, another exception occurred:

MemoryError

During handling of the above exception, another exception occurred:



During handling of the above exception, another exception occurred:

MemoryError

During handling of the above exception, another exception occurred:



During handling of the above exception, another exception occurred:

MemoryError

During handling of the above exception, another exception occurred:

MemoryError
Exception ignored in: Traceback (most recent call last):
  File "/home/weit/anaconda3/envs/cc-env/lib/python3.7/runpy.py", line 193, in _run_module_as_main
    "__main__", mod_spec)
  File "/home/weit/anaconda3/envs/cc-env/lib/python3.7/runpy.py", line 85, in _run_code
    exec(code, run_globals)
  File "/home/weit/circuit_cutting/utils/evaluator.py", line 1, in <module>
    from qiskit.converters import circuit_to_dag, dag_to_circuit
  File "/home/weit/anaconda3/envs/cc-env/lib/python3.7/site-packages/qiskit/__init__.py", line 30, in <module>
    from qiskit.circuit import ClassicalRegister
  File "/home/weit/anaconda3/envs/cc-env/lib/python3.7/site-packages/qiskit/circuit/__init__.py", line 60, in <module>
    from .gate import Gate
  File "/home/weit/anaconda3/envs/cc-env/lib/python3.7/site-packages/qiskit/circuit/gate.py", line 18, in <module>
    from scipy.linalg import schur
  File "/home/weit/anaconda3/envs/cc-env/lib/python3.7/site-packages/scipy/linalg/__init__.py", line 195, in <module>
    from .misc import *
  File "/home/weit/anaconda3/envs/cc-env/lib/python3.7/site-packages/scipy/linalg/misc.py", line 6, in <module>
    from .lapack import get_lapack_funcs
  File "/home/weit/anaconda3/envs/cc-env/lib/python3.7/site-packages/scipy/linalg/lapack.py", line 664, in <module>
    from scipy.linalg import _flapack
ImportError: /home/weit/anaconda3/envs/cc-env/lib/python3.7/site-packages/scipy/linalg/_flapack.cpython-37m-x86_64-linux-gnu.so: failed to map segment from shared object
Traceback (most recent call last):
  File "/home/weit/anaconda3/envs/cc-env/lib/python3.7/runpy.py", line 193, in _run_module_as_main
    "__main__", mod_spec)
  File "/home/weit/anaconda3/envs/cc-env/lib/python3.7/runpy.py", line 85, in _run_code
    exec(code, run_globals)
  File "/home/weit/circuit_cutting/utils/evaluator.py", line 1, in <module>
    from qiskit.converters import circuit_to_dag, dag_to_circuit
  File "/home/weit/anaconda3/envs/cc-env/lib/python3.7/site-packages/qiskit/__init__.py", line 30, in <module>
    from qiskit.circuit import ClassicalRegister
  File "/home/weit/anaconda3/envs/cc-env/lib/python3.7/site-packages/qiskit/circuit/__init__.py", line 60, in <module>
    from .gate import Gate
  File "/home/weit/anaconda3/envs/cc-env/lib/python3.7/site-packages/qiskit/circuit/gate.py", line 18, in <module>
    from scipy.linalg import schur
  File "/home/weit/anaconda3/envs/cc-env/lib/python3.7/site-packages/scipy/linalg/__init__.py", line 195, in <module>
    from .misc import *
  File "/home/weit/anaconda3/envs/cc-env/lib/python3.7/site-packages/scipy/linalg/misc.py", line 6, in <module>
    from .lapack import get_lapack_funcs
  File "/home/weit/anaconda3/envs/cc-env/lib/python3.7/site-packages/scipy/linalg/lapack.py", line 664, in <module>
    from scipy.linalg import _flapack
ImportError: /home/weit/anaconda3/envs/cc-env/lib/python3.7/site-packages/scipy/linalg/_flapack.cpython-37m-x86_64-linux-gnu.so: failed to map segment from shared object
Traceback (most recent call last):
  File "/home/weit/anaconda3/envs/cc-env/lib/python3.7/runpy.py", line 193, in _run_module_as_main
    "__main__", mod_spec)
  File "/home/weit/anaconda3/envs/cc-env/lib/python3.7/runpy.py", line 85, in _run_code
    exec(code, run_globals)
  File "/home/weit/circuit_cutting/utils/evaluator.py", line 1, in <module>
    from qiskit.converters import circuit_to_dag, dag_to_circuit
  File "/home/weit/anaconda3/envs/cc-env/lib/python3.7/site-packages/qiskit/__init__.py", line 30, in <module>
    from qiskit.circuit import ClassicalRegister
  File "/home/weit/anaconda3/envs/cc-env/lib/python3.7/site-packages/qiskit/circuit/__init__.py", line 60, in <module>
    from .gate import Gate
  File "/home/weit/anaconda3/envs/cc-env/lib/python3.7/site-packages/qiskit/circuit/gate.py", line 18, in <module>
    from scipy.linalg import schur
  File "/home/weit/anaconda3/envs/cc-env/lib/python3.7/site-packages/scipy/linalg/__init__.py", line 212, in <module>
    from ._decomp_update import *
ImportError: /home/weit/anaconda3/envs/cc-env/lib/python3.7/site-packages/scipy/linalg/_decomp_update.cpython-37m-x86_64-linux-gnu.so: failed to map segment from shared object
Traceback (most recent call last):
  File "/home/weit/anaconda3/envs/cc-env/lib/python3.7/runpy.py", line 193, in _run_module_as_main
    "__main__", mod_spec)
  File "/home/weit/anaconda3/envs/cc-env/lib/python3.7/runpy.py", line 85, in _run_code
    exec(code, run_globals)
  File "/home/weit/circuit_cutting/utils/evaluator.py", line 1, in <module>
    from qiskit.converters import circuit_to_dag, dag_to_circuit
  File "/home/weit/anaconda3/envs/cc-env/lib/python3.7/site-packages/qiskit/__init__.py", line 30, in <module>
    from qiskit.circuit import ClassicalRegister
  File "/home/weit/anaconda3/envs/cc-env/lib/python3.7/site-packages/qiskit/circuit/__init__.py", line 60, in <module>
    from .gate import Gate
  File "/home/weit/anaconda3/envs/cc-env/lib/python3.7/site-packages/qiskit/circuit/gate.py", line 18, in <module>
    from scipy.linalg import schur
  File "/home/weit/anaconda3/envs/cc-env/lib/python3.7/site-packages/scipy/linalg/__init__.py", line 195, in <module>
    from .misc import *
  File "/home/weit/anaconda3/envs/cc-env/lib/python3.7/site-packages/scipy/linalg/misc.py", line 6, in <module>
    from .lapack import get_lapack_funcs
  File "/home/weit/anaconda3/envs/cc-env/lib/python3.7/site-packages/scipy/linalg/lapack.py", line 664, in <module>
    from scipy.linalg import _flapack
ImportError: /home/weit/anaconda3/envs/cc-env/lib/python3.7/site-packages/scipy/linalg/_flapack.cpython-37m-x86_64-linux-gnu.so: failed to map segment from shared object
Traceback (most recent call last):
  File "/home/weit/anaconda3/envs/cc-env/lib/python3.7/runpy.py", line 193, in _run_module_as_main
    "__main__", mod_spec)
  File "/home/weit/anaconda3/envs/cc-env/lib/python3.7/runpy.py", line 85, in _run_code
    exec(code, run_globals)
  File "/home/weit/circuit_cutting/utils/evaluator.py", line 1, in <module>
    from qiskit.converters import circuit_to_dag, dag_to_circuit
  File "/home/weit/anaconda3/envs/cc-env/lib/python3.7/site-packages/qiskit/__init__.py", line 30, in <module>
    from qiskit.circuit import ClassicalRegister
  File "/home/weit/anaconda3/envs/cc-env/lib/python3.7/site-packages/qiskit/circuit/__init__.py", line 60, in <module>
    from .gate import Gate
  File "/home/weit/anaconda3/envs/cc-env/lib/python3.7/site-packages/qiskit/circuit/gate.py", line 18, in <module>
    from scipy.linalg import schur
  File "/home/weit/anaconda3/envs/cc-env/lib/python3.7/site-packages/scipy/linalg/__init__.py", line 196, in <module>
    from .basic import *
  File "/home/weit/anaconda3/envs/cc-env/lib/python3.7/site-packages/scipy/linalg/basic.py", line 17, in <module>
    from ._solve_toeplitz import levinson
ImportError: /home/weit/anaconda3/envs/cc-env/lib/python3.7/site-packages/scipy/linalg/_solve_toeplitz.cpython-37m-x86_64-linux-gnu.so: failed to map segment from shared object
Traceback (most recent call last):
  File "/home/weit/anaconda3/envs/cc-env/lib/python3.7/runpy.py", line 193, in _run_module_as_main
    "__main__", mod_spec)
  File "/home/weit/anaconda3/envs/cc-env/lib/python3.7/runpy.py", line 85, in _run_code
    exec(code, run_globals)
  File "/home/weit/circuit_cutting/utils/evaluator.py", line 1, in <module>
    from qiskit.converters import circuit_to_dag, dag_to_circuit
  File "/home/weit/anaconda3/envs/cc-env/lib/python3.7/site-packages/qiskit/__init__.py", line 30, in <module>
    from qiskit.circuit import ClassicalRegister
  File "/home/weit/anaconda3/envs/cc-env/lib/python3.7/site-packages/qiskit/circuit/__init__.py", line 60, in <module>
    from .gate import Gate
  File "/home/weit/anaconda3/envs/cc-env/lib/python3.7/site-packages/qiskit/circuit/gate.py", line 18, in <module>
    from scipy.linalg import schur
  File "/home/weit/anaconda3/envs/cc-env/lib/python3.7/site-packages/scipy/linalg/__init__.py", line 196, in <module>
    from .basic import *
  File "/home/weit/anaconda3/envs/cc-env/lib/python3.7/site-packages/scipy/linalg/basic.py", line 17, in <module>
    from ._solve_toeplitz import levinson
ImportError: /home/weit/anaconda3/envs/cc-env/lib/python3.7/site-packages/scipy/linalg/_solve_toeplitz.cpython-37m-x86_64-linux-gnu.so: failed to map segment from shared object
Traceback (most recent call last):
  File "/home/weit/anaconda3/envs/cc-env/lib/python3.7/runpy.py", line 193, in _run_module_as_main
    "__main__", mod_spec)
  File "/home/weit/anaconda3/envs/cc-env/lib/python3.7/runpy.py", line 85, in _run_code
    exec(code, run_globals)
  File "/home/weit/circuit_cutting/utils/evaluator.py", line 1, in <module>
    from qiskit.converters import circuit_to_dag, dag_to_circuit
  File "/home/weit/anaconda3/envs/cc-env/lib/python3.7/site-packages/qiskit/__init__.py", line 30, in <module>
    from qiskit.circuit import ClassicalRegister
  File "/home/weit/anaconda3/envs/cc-env/lib/python3.7/site-packages/qiskit/circuit/__init__.py", line 60, in <module>
    from .gate import Gate
  File "/home/weit/anaconda3/envs/cc-env/lib/python3.7/site-packages/qiskit/circuit/gate.py", line 18, in <module>
    from scipy.linalg import schur
  File "/home/weit/anaconda3/envs/cc-env/lib/python3.7/site-packages/scipy/linalg/__init__.py", line 196, in <module>
    from .basic import *
  File "/home/weit/anaconda3/envs/cc-env/lib/python3.7/site-packages/scipy/linalg/basic.py", line 17, in <module>
    from ._solve_toeplitz import levinson
ImportError: /home/weit/anaconda3/envs/cc-env/lib/python3.7/site-packages/scipy/linalg/_solve_toeplitz.cpython-37m-x86_64-linux-gnu.so: failed to map segment from shared object
Traceback (most recent call last):
  File "/home/weit/anaconda3/envs/cc-env/lib/python3.7/runpy.py", line 193, in _run_module_as_main
    "__main__", mod_spec)
  File "/home/weit/anaconda3/envs/cc-env/lib/python3.7/runpy.py", line 85, in _run_code
    exec(code, run_globals)
  File "/home/weit/circuit_cutting/utils/evaluator.py", line 1, in <module>
    from qiskit.converters import circuit_to_dag, dag_to_circuit
  File "/home/weit/anaconda3/envs/cc-env/lib/python3.7/site-packages/qiskit/__init__.py", line 30, in <module>
    from qiskit.circuit import ClassicalRegister
  File "/home/weit/anaconda3/envs/cc-env/lib/python3.7/site-packages/qiskit/circuit/__init__.py", line 60, in <module>
    from .gate import Gate
  File "/home/weit/anaconda3/envs/cc-env/lib/python3.7/site-packages/qiskit/circuit/gate.py", line 18, in <module>
    from scipy.linalg import schur
  File "/home/weit/anaconda3/envs/cc-env/lib/python3.7/site-packages/scipy/linalg/__init__.py", line 213, in <module>
    from ._sketches import *
  File "/home/weit/anaconda3/envs/cc-env/lib/python3.7/site-packages/scipy/linalg/_sketches.py", line 11, in <module>
    from scipy.sparse import csc_matrix
  File "/home/weit/anaconda3/envs/cc-env/lib/python3.7/site-packages/scipy/sparse/__init__.py", line 230, in <module>
    from .csr import *
  File "/home/weit/anaconda3/envs/cc-env/lib/python3.7/site-packages/scipy/sparse/csr.py", line 13, in <module>
    from ._sparsetools import (csr_tocsc, csr_tobsr, csr_count_blocks,
ImportError: /home/weit/anaconda3/envs/cc-env/lib/python3.7/site-packages/scipy/sparse/_sparsetools.cpython-37m-x86_64-linux-gnu.so: failed to map segment from shared object
Traceback (most recent call last):
  File "/home/weit/anaconda3/envs/cc-env/lib/python3.7/runpy.py", line 193, in _run_module_as_main
  File "/home/weit/anaconda3/envs/cc-env/lib/python3.7/runpy.py", line 85, in _run_code
  File "/home/weit/circuit_cutting/utils/evaluator.py", line 1, in <module>
  File "/home/weit/anaconda3/envs/cc-env/lib/python3.7/site-packages/qiskit/__init__.py", line 30, in <module>
    from qiskit.circuit import ClassicalRegister
  File "/home/weit/anaconda3/envs/cc-env/lib/python3.7/site-packages/qiskit/circuit/__init__.py", line 57, in <module>
    from .quantumcircuit import QuantumCircuit
  File "/home/weit/anaconda3/envs/cc-env/lib/python3.7/site-packages/qiskit/circuit/quantumcircuit.py", line 22, in <module>
  File "/home/weit/anaconda3/envs/cc-env/lib/python3.7/site-packages/qiskit/circuit/instruction.py", line 45, in <module>
  File "/home/weit/anaconda3/envs/cc-env/lib/python3.7/site-packages/qiskit/qobj/__init__.py", line 76, in <module>
    from .models.pulse import (PulseQobjInstruction, PulseQobjExperimentConfig,
  File "/home/weit/anaconda3/envs/cc-env/lib/python3.7/site-packages/qiskit/qobj/models/pulse.py", line 19, in <module>
    from qiskit.qobj.utils import MeasReturnType, MeasLevel
  File "/home/weit/anaconda3/envs/cc-env/lib/python3.7/site-packages/qiskit/qobj/utils.py", line 19, in <module>
    from qiskit.validation.jsonschema import validate_json_against_schema
  File "/home/weit/anaconda3/envs/cc-env/lib/python3.7/site-packages/qiskit/validation/jsonschema/__init__.py", line 18, in <module>
    from .schema_validation import validate_json_against_schema
  File "/home/weit/anaconda3/envs/cc-env/lib/python3.7/site-packages/qiskit/validation/jsonschema/schema_validation.py", line 20, in <module>
    import jsonschema
  File "/home/weit/anaconda3/envs/cc-env/lib/python3.7/site-packages/jsonschema/__init__.py", line 34, in <module>
    __version__ = metadata.version("jsonschema")
  File "/home/weit/anaconda3/envs/cc-env/lib/python3.7/site-packages/importlib_metadata/__init__.py", line 516, in version
    return distribution(distribution_name).version
  File "/home/weit/anaconda3/envs/cc-env/lib/python3.7/site-packages/importlib_metadata/__init__.py", line 253, in version
    return self.metadata['Version']
  File "/home/weit/anaconda3/envs/cc-env/lib/python3.7/site-packages/importlib_metadata/__init__.py", line 248, in metadata
    return email_message_from_string(text)
  File "/home/weit/anaconda3/envs/cc-env/lib/python3.7/email/__init__.py", line 38, in message_from_string
    return Parser(*args, **kws).parsestr(s)
  File "/home/weit/anaconda3/envs/cc-env/lib/python3.7/email/parser.py", line 67, in parsestr
    return self.parse(StringIO(text), headersonly=headersonly)
  File "/home/weit/anaconda3/envs/cc-env/lib/python3.7/email/parser.py", line 56, in parse
    feedparser.feed(data)
  File "/home/weit/anaconda3/envs/cc-env/lib/python3.7/email/feedparser.py", line 175, in feed
    self._input.push(data)
  File "/home/weit/anaconda3/envs/cc-env/lib/python3.7/email/feedparser.py", line 110, in push
    parts = self._partial.readlines()
MemoryError
Traceback (most recent call last):
  File "/home/weit/anaconda3/envs/cc-env/lib/python3.7/runpy.py", line 193, in _run_module_as_main
  File "/home/weit/anaconda3/envs/cc-env/lib/python3.7/runpy.py", line 85, in _run_code
  File "/home/weit/circuit_cutting/utils/evaluator.py", line 1, in <module>
  File "/home/weit/anaconda3/envs/cc-env/lib/python3.7/site-packages/qiskit/__init__.py", line 30, in <module>
    from qiskit.circuit import ClassicalRegister
  File "/home/weit/anaconda3/envs/cc-env/lib/python3.7/site-packages/qiskit/circuit/__init__.py", line 57, in <module>
    from .quantumcircuit import QuantumCircuit
  File "/home/weit/anaconda3/envs/cc-env/lib/python3.7/site-packages/qiskit/circuit/quantumcircuit.py", line 22, in <module>
  File "/home/weit/anaconda3/envs/cc-env/lib/python3.7/site-packages/qiskit/circuit/instruction.py", line 45, in <module>
  File "/home/weit/anaconda3/envs/cc-env/lib/python3.7/site-packages/qiskit/qobj/__init__.py", line 76, in <module>
    from .models.pulse import (PulseQobjInstruction, PulseQobjExperimentConfig,
  File "/home/weit/anaconda3/envs/cc-env/lib/python3.7/site-packages/qiskit/qobj/models/pulse.py", line 19, in <module>
    from qiskit.qobj.utils import MeasReturnType, MeasLevel
  File "/home/weit/anaconda3/envs/cc-env/lib/python3.7/site-packages/qiskit/qobj/utils.py", line 19, in <module>
    from qiskit.validation.jsonschema import validate_json_against_schema
  File "/home/weit/anaconda3/envs/cc-env/lib/python3.7/site-packages/qiskit/validation/jsonschema/__init__.py", line 18, in <module>
    from .schema_validation import validate_json_against_schema
  File "/home/weit/anaconda3/envs/cc-env/lib/python3.7/site-packages/qiskit/validation/jsonschema/schema_validation.py", line 20, in <module>
    import jsonschema
  File "/home/weit/anaconda3/envs/cc-env/lib/python3.7/site-packages/jsonschema/__init__.py", line 34, in <module>
    __version__ = metadata.version("jsonschema")
  File "/home/weit/anaconda3/envs/cc-env/lib/python3.7/site-packages/importlib_metadata/__init__.py", line 516, in version
    return distribution(distribution_name).version
  File "/home/weit/anaconda3/envs/cc-env/lib/python3.7/site-packages/importlib_metadata/__init__.py", line 253, in version
    return self.metadata['Version']
  File "/home/weit/anaconda3/envs/cc-env/lib/python3.7/site-packages/importlib_metadata/__init__.py", line 248, in metadata
    return email_message_from_string(text)
  File "/home/weit/anaconda3/envs/cc-env/lib/python3.7/email/__init__.py", line 38, in message_from_string
    return Parser(*args, **kws).parsestr(s)
  File "/home/weit/anaconda3/envs/cc-env/lib/python3.7/email/parser.py", line 67, in parsestr
    return self.parse(StringIO(text), headersonly=headersonly)
  File "/home/weit/anaconda3/envs/cc-env/lib/python3.7/email/parser.py", line 56, in parse
    feedparser.feed(data)
  File "/home/weit/anaconda3/envs/cc-env/lib/python3.7/email/feedparser.py", line 175, in feed
    self._input.push(data)
  File "/home/weit/anaconda3/envs/cc-env/lib/python3.7/email/feedparser.py", line 110, in push
    parts = self._partial.readlines()
MemoryError
Traceback (most recent call last):
  File "/home/weit/anaconda3/envs/cc-env/lib/python3.7/runpy.py", line 193, in _run_module_as_main
  File "/home/weit/anaconda3/envs/cc-env/lib/python3.7/runpy.py", line 85, in _run_code
  File "/home/weit/circuit_cutting/utils/evaluator.py", line 1, in <module>
  File "/home/weit/anaconda3/envs/cc-env/lib/python3.7/site-packages/qiskit/__init__.py", line 30, in <module>
    from qiskit.circuit import ClassicalRegister
  File "/home/weit/anaconda3/envs/cc-env/lib/python3.7/site-packages/qiskit/circuit/__init__.py", line 57, in <module>
    from .quantumcircuit import QuantumCircuit
  File "/home/weit/anaconda3/envs/cc-env/lib/python3.7/site-packages/qiskit/circuit/quantumcircuit.py", line 22, in <module>
  File "/home/weit/anaconda3/envs/cc-env/lib/python3.7/site-packages/qiskit/circuit/instruction.py", line 45, in <module>
  File "/home/weit/anaconda3/envs/cc-env/lib/python3.7/site-packages/qiskit/qobj/__init__.py", line 76, in <module>
    from .models.pulse import (PulseQobjInstruction, PulseQobjExperimentConfig,
  File "/home/weit/anaconda3/envs/cc-env/lib/python3.7/site-packages/qiskit/qobj/models/pulse.py", line 19, in <module>
    from qiskit.qobj.utils import MeasReturnType, MeasLevel
  File "/home/weit/anaconda3/envs/cc-env/lib/python3.7/site-packages/qiskit/qobj/utils.py", line 19, in <module>
    from qiskit.validation.jsonschema import validate_json_against_schema
  File "/home/weit/anaconda3/envs/cc-env/lib/python3.7/site-packages/qiskit/validation/jsonschema/__init__.py", line 18, in <module>
    from .schema_validation import validate_json_against_schema
  File "/home/weit/anaconda3/envs/cc-env/lib/python3.7/site-packages/qiskit/validation/jsonschema/schema_validation.py", line 20, in <module>
    import jsonschema
  File "/home/weit/anaconda3/envs/cc-env/lib/python3.7/site-packages/jsonschema/__init__.py", line 34, in <module>
    __version__ = metadata.version("jsonschema")
  File "/home/weit/anaconda3/envs/cc-env/lib/python3.7/site-packages/importlib_metadata/__init__.py", line 516, in version
    return distribution(distribution_name).version
  File "/home/weit/anaconda3/envs/cc-env/lib/python3.7/site-packages/importlib_metadata/__init__.py", line 253, in version
    return self.metadata['Version']
  File "/home/weit/anaconda3/envs/cc-env/lib/python3.7/site-packages/importlib_metadata/__init__.py", line 248, in metadata
    return email_message_from_string(text)
  File "/home/weit/anaconda3/envs/cc-env/lib/python3.7/email/__init__.py", line 38, in message_from_string
    return Parser(*args, **kws).parsestr(s)
  File "/home/weit/anaconda3/envs/cc-env/lib/python3.7/email/parser.py", line 67, in parsestr
    return self.parse(StringIO(text), headersonly=headersonly)
  File "/home/weit/anaconda3/envs/cc-env/lib/python3.7/email/parser.py", line 56, in parse
    feedparser.feed(data)
  File "/home/weit/anaconda3/envs/cc-env/lib/python3.7/email/feedparser.py", line 175, in feed
    self._input.push(data)
  File "/home/weit/anaconda3/envs/cc-env/lib/python3.7/email/feedparser.py", line 110, in push
    parts = self._partial.readlines()
MemoryError
Traceback (most recent call last):
  File "/home/weit/anaconda3/envs/cc-env/lib/python3.7/runpy.py", line 193, in _run_module_as_main
    "__main__", mod_spec)
  File "/home/weit/anaconda3/envs/cc-env/lib/python3.7/runpy.py", line 85, in _run_code
    exec(code, run_globals)
  File "/home/weit/circuit_cutting/utils/evaluator.py", line 1, in <module>
    from qiskit.converters import circuit_to_dag, dag_to_circuit
  File "/home/weit/anaconda3/envs/cc-env/lib/python3.7/site-packages/qiskit/__init__.py", line 30, in <module>
    from qiskit.circuit import ClassicalRegister
  File "/home/weit/anaconda3/envs/cc-env/lib/python3.7/site-packages/qiskit/circuit/__init__.py", line 57, in <module>
    from .quantumcircuit import QuantumCircuit
  File "/home/weit/anaconda3/envs/cc-env/lib/python3.7/site-packages/qiskit/circuit/quantumcircuit.py", line 22, in <module>
    from qiskit.circuit.instruction import Instruction
  File "/home/weit/anaconda3/envs/cc-env/lib/python3.7/site-packages/qiskit/circuit/instruction.py", line 45, in <module>
    from qiskit.qobj.models.qasm import QasmQobjInstruction
  File "/home/weit/anaconda3/envs/cc-env/lib/python3.7/site-packages/qiskit/qobj/__init__.py", line 76, in <module>
    from .models.pulse import (PulseQobjInstruction, PulseQobjExperimentConfig,
  File "/home/weit/anaconda3/envs/cc-env/lib/python3.7/site-packages/qiskit/qobj/models/pulse.py", line 19, in <module>
    from qiskit.qobj.utils import MeasReturnType, MeasLevel
  File "/home/weit/anaconda3/envs/cc-env/lib/python3.7/site-packages/qiskit/qobj/utils.py", line 19, in <module>
    from qiskit.validation.jsonschema import validate_json_against_schema
  File "/home/weit/anaconda3/envs/cc-env/lib/python3.7/site-packages/qiskit/validation/jsonschema/__init__.py", line 18, in <module>
    from .schema_validation import validate_json_against_schema
  File "/home/weit/anaconda3/envs/cc-env/lib/python3.7/site-packages/qiskit/validation/jsonschema/schema_validation.py", line 20, in <module>
    import jsonschema
  File "/home/weit/anaconda3/envs/cc-env/lib/python3.7/site-packages/jsonschema/__init__.py", line 21, in <module>
    from jsonschema._types import TypeChecker
  File "/home/weit/anaconda3/envs/cc-env/lib/python3.7/site-packages/jsonschema/_types.py", line 49, in <module>
    class TypeChecker(object):
  File "/home/weit/anaconda3/envs/cc-env/lib/python3.7/site-packages/attr/_make.py", line 970, in wrap
    builder.add_eq()
  File "/home/weit/anaconda3/envs/cc-env/lib/python3.7/site-packages/attr/_make.py", line 700, in add_eq
    for meth in _make_eq(self._cls, self._attrs)
  File "/home/weit/anaconda3/envs/cc-env/lib/python3.7/site-packages/attr/_make.py", line 1193, in _make_eq
    bytecode = compile(script, unique_filename, "exec")
MemoryError
Traceback (most recent call last):
  File "/home/weit/anaconda3/envs/cc-env/lib/python3.7/runpy.py", line 193, in _run_module_as_main
    "__main__", mod_spec)
  File "/home/weit/anaconda3/envs/cc-env/lib/python3.7/runpy.py", line 85, in _run_code
    exec(code, run_globals)
  File "/home/weit/circuit_cutting/utils/evaluator.py", line 1, in <module>
    from qiskit.converters import circuit_to_dag, dag_to_circuit
  File "/home/weit/anaconda3/envs/cc-env/lib/python3.7/site-packages/qiskit/__init__.py", line 30, in <module>
    from qiskit.circuit import ClassicalRegister
  File "/home/weit/anaconda3/envs/cc-env/lib/python3.7/site-packages/qiskit/circuit/__init__.py", line 57, in <module>
    from .quantumcircuit import QuantumCircuit
  File "/home/weit/anaconda3/envs/cc-env/lib/python3.7/site-packages/qiskit/circuit/quantumcircuit.py", line 22, in <module>
    from qiskit.circuit.instruction import Instruction
  File "/home/weit/anaconda3/envs/cc-env/lib/python3.7/site-packages/qiskit/circuit/instruction.py", line 45, in <module>
    from qiskit.qobj.models.qasm import QasmQobjInstruction
  File "/home/weit/anaconda3/envs/cc-env/lib/python3.7/site-packages/qiskit/qobj/__init__.py", line 76, in <module>
    from .models.pulse import (PulseQobjInstruction, PulseQobjExperimentConfig,
  File "/home/weit/anaconda3/envs/cc-env/lib/python3.7/site-packages/qiskit/qobj/models/pulse.py", line 19, in <module>
    from qiskit.qobj.utils import MeasReturnType, MeasLevel
  File "/home/weit/anaconda3/envs/cc-env/lib/python3.7/site-packages/qiskit/qobj/utils.py", line 19, in <module>
    from qiskit.validation.jsonschema import validate_json_against_schema
  File "/home/weit/anaconda3/envs/cc-env/lib/python3.7/site-packages/qiskit/validation/jsonschema/__init__.py", line 18, in <module>
    from .schema_validation import validate_json_against_schema
  File "/home/weit/anaconda3/envs/cc-env/lib/python3.7/site-packages/qiskit/validation/jsonschema/schema_validation.py", line 113, in <module>
    _load_schemas_and_validators()
  File "/home/weit/anaconda3/envs/cc-env/lib/python3.7/site-packages/qiskit/validation/jsonschema/schema_validation.py", line 108, in _load_schemas_and_validators
    _load_schema(os.path.join(schema_base_path, path), name)
  File "/home/weit/anaconda3/envs/cc-env/lib/python3.7/site-packages/qiskit/validation/jsonschema/schema_validation.py", line 57, in _load_schema
    _SCHEMAS[name] = json.load(schema_file)
  File "/home/weit/anaconda3/envs/cc-env/lib/python3.7/json/__init__.py", line 293, in load
    return loads(fp.read(),
  File "/home/weit/anaconda3/envs/cc-env/lib/python3.7/codecs.py", line 322, in decode
    (result, consumed) = self._buffer_decode(data, self.errors, final)
MemoryError
Traceback (most recent call last):
  File "/home/weit/anaconda3/envs/cc-env/lib/python3.7/runpy.py", line 193, in _run_module_as_main
    "__main__", mod_spec)
  File "/home/weit/anaconda3/envs/cc-env/lib/python3.7/runpy.py", line 85, in _run_code
    exec(code, run_globals)
  File "/home/weit/circuit_cutting/utils/evaluator.py", line 1, in <module>
    from qiskit.converters import circuit_to_dag, dag_to_circuit
  File "/home/weit/anaconda3/envs/cc-env/lib/python3.7/site-packages/qiskit/__init__.py", line 30, in <module>
    from qiskit.circuit import ClassicalRegister
  File "/home/weit/anaconda3/envs/cc-env/lib/python3.7/site-packages/qiskit/circuit/__init__.py", line 57, in <module>
    from .quantumcircuit import QuantumCircuit
  File "/home/weit/anaconda3/envs/cc-env/lib/python3.7/site-packages/qiskit/circuit/quantumcircuit.py", line 22, in <module>
    from qiskit.circuit.instruction import Instruction
  File "/home/weit/anaconda3/envs/cc-env/lib/python3.7/site-packages/qiskit/circuit/instruction.py", line 45, in <module>
    from qiskit.qobj.models.qasm import QasmQobjInstruction
  File "/home/weit/anaconda3/envs/cc-env/lib/python3.7/site-packages/qiskit/qobj/__init__.py", line 76, in <module>
    from .models.pulse import (PulseQobjInstruction, PulseQobjExperimentConfig,
  File "/home/weit/anaconda3/envs/cc-env/lib/python3.7/site-packages/qiskit/qobj/models/pulse.py", line 19, in <module>
    from qiskit.qobj.utils import MeasReturnType, MeasLevel
  File "/home/weit/anaconda3/envs/cc-env/lib/python3.7/site-packages/qiskit/qobj/utils.py", line 19, in <module>
    from qiskit.validation.jsonschema import validate_json_against_schema
  File "/home/weit/anaconda3/envs/cc-env/lib/python3.7/site-packages/qiskit/validation/jsonschema/__init__.py", line 18, in <module>
    from .schema_validation import validate_json_against_schema
  File "/home/weit/anaconda3/envs/cc-env/lib/python3.7/site-packages/qiskit/validation/jsonschema/schema_validation.py", line 113, in <module>
    _load_schemas_and_validators()
  File "/home/weit/anaconda3/envs/cc-env/lib/python3.7/site-packages/qiskit/validation/jsonschema/schema_validation.py", line 108, in _load_schemas_and_validators
    _load_schema(os.path.join(schema_base_path, path), name)
  File "/home/weit/anaconda3/envs/cc-env/lib/python3.7/site-packages/qiskit/validation/jsonschema/schema_validation.py", line 57, in _load_schema
    _SCHEMAS[name] = json.load(schema_file)
  File "/home/weit/anaconda3/envs/cc-env/lib/python3.7/json/__init__.py", line 293, in load
    return loads(fp.read(),
  File "/home/weit/anaconda3/envs/cc-env/lib/python3.7/codecs.py", line 322, in decode
    (result, consumed) = self._buffer_decode(data, self.errors, final)
MemoryError
Traceback (most recent call last):
  File "/home/weit/anaconda3/envs/cc-env/lib/python3.7/runpy.py", line 193, in _run_module_as_main
    "__main__", mod_spec)
  File "/home/weit/anaconda3/envs/cc-env/lib/python3.7/runpy.py", line 85, in _run_code
    exec(code, run_globals)
  File "/home/weit/circuit_cutting/utils/evaluator.py", line 1, in <module>
    from qiskit.converters import circuit_to_dag, dag_to_circuit
  File "/home/weit/anaconda3/envs/cc-env/lib/python3.7/site-packages/qiskit/__init__.py", line 36, in <module>
    import qiskit.extensions
  File "/home/weit/anaconda3/envs/cc-env/lib/python3.7/site-packages/qiskit/extensions/__init__.py", line 83, in <module>
    from qiskit.extensions.quantum_initializer.initializer import Initialize
  File "/home/weit/anaconda3/envs/cc-env/lib/python3.7/site-packages/qiskit/extensions/quantum_initializer/__init__.py", line 17, in <module>
    from .squ import SingleQubitUnitary
  File "/home/weit/anaconda3/envs/cc-env/lib/python3.7/site-packages/qiskit/extensions/quantum_initializer/squ.py", line 32, in <module>
    from qiskit.quantum_info.operators.predicates import is_unitary_matrix
  File "/home/weit/anaconda3/envs/cc-env/lib/python3.7/site-packages/qiskit/quantum_info/__init__.py", line 99, in <module>
    from .random import random_unitary, random_state, random_density_matrix
  File "/home/weit/anaconda3/envs/cc-env/lib/python3.7/site-packages/qiskit/quantum_info/random/__init__.py", line 17, in <module>
    from .utils import random_unitary, random_state, random_density_matrix
  File "/home/weit/anaconda3/envs/cc-env/lib/python3.7/site-packages/qiskit/quantum_info/random/utils.py", line 21, in <module>
    from scipy.stats import unitary_group
  File "/home/weit/anaconda3/envs/cc-env/lib/python3.7/site-packages/scipy/stats/__init__.py", line 386, in <module>
    from .morestats import *
  File "/home/weit/anaconda3/envs/cc-env/lib/python3.7/site-packages/scipy/stats/morestats.py", line 16, in <module>
    from . import statlib
ImportError: /home/weit/anaconda3/envs/cc-env/lib/python3.7/site-packages/scipy/stats/statlib.cpython-37m-x86_64-linux-gnu.so: failed to map segment from shared object
