Using license file /Users/weitang/gurobi.lic
Academic license - for non-commercial use only
case (11, 16)
Searcher time = 0.424, 4 cuts
Cluster 0: 9-qubit, 4 ρ-qubit + 0 O-qubit = 1296 instances
Cluster 1: 11-qubit, 0 ρ-qubit + 4 O-qubit = 81 instances
qc_time = 4.147 seconds, qc_mem = 0.000000 TB
std_time = 0.658 seconds, std_mem = 0.000000 TB
--------------------------------------------------
-------------------------------------------------- Evaluator --------------------------------------------------
Existing cases: dict_keys([])
Running case: (11, 16)
Case (11, 16), cluster_0 9_qubits * 1296_instances on fake QUANTUM SIMULATOR, 
Case (11, 16), cluster_1 11_qubits * 81_instances on fake QUANTUM SIMULATOR, 
dumped case (11, 16), 1/1 cases
----------------------------------------------------------------------------------------------------
-------------------------------------------------- Reconstructor --------------------------------------------------
Existing cases: dict_keys([])
case (11, 16)
Traceback (most recent call last):
  File "/Users/weitang/opt/anaconda3/envs/cc-env/lib/python3.7/runpy.py", line 193, in _run_module_as_main
    "__main__", mod_spec)
  File "/Users/weitang/opt/anaconda3/envs/cc-env/lib/python3.7/runpy.py", line 85, in _run_code
    exec(code, run_globals)
  File "/Users/weitang/Documents/circuit_cutting/scalability/fake_reconstructor.py", line 88, in <module>
    states=range(1000))
  File "/Users/weitang/Documents/circuit_cutting/scalability/fake_reconstruct_helper_fun.py", line 26, in fake_reconstruct
    clusters_init_meas = find_inits_meas(cluster_circs, O_rho_pairs, s)
NameError: name 'cluster_circs' is not defined
Cut into [ 9 11] clusters
smart order: (0, 1)
-------------------------------------------------- Reconstructor --------------------------------------------------
Existing cases: dict_keys([])
case (11, 16)
Traceback (most recent call last):
  File "/Users/weitang/opt/anaconda3/envs/cc-env/lib/python3.7/runpy.py", line 193, in _run_module_as_main
    "__main__", mod_spec)
  File "/Users/weitang/opt/anaconda3/envs/cc-env/lib/python3.7/runpy.py", line 85, in _run_code
    exec(code, run_globals)
  File "/Users/weitang/Documents/circuit_cutting/scalability/fake_reconstructor.py", line 88, in <module>
    states=range(1000))
ValueError: not enough values to unpack (expected 4, got 3)
Cut into [ 9 11] clusters
smart order: (0, 1)
-------------------------------------------------- Reconstructor --------------------------------------------------
Existing cases: dict_keys([])
case (11, 16)
Traceback (most recent call last):
  File "/Users/weitang/opt/anaconda3/envs/cc-env/lib/python3.7/runpy.py", line 193, in _run_module_as_main
    "__main__", mod_spec)
  File "/Users/weitang/opt/anaconda3/envs/cc-env/lib/python3.7/runpy.py", line 85, in _run_code
    exec(code, run_globals)
  File "/Users/weitang/Documents/circuit_cutting/scalability/fake_reconstructor.py", line 89, in <module>
    compute_time = time() - compute_begin + total_estimated_kron_time
NameError: name 'total_estimated_kron_time' is not defined
Cut into [ 9 11] clusters
smart order: (0, 1)
-------------------------------------------------- Reconstructor --------------------------------------------------
Existing cases: dict_keys([])
case (11, 16)
Traceback (most recent call last):
  File "/Users/weitang/opt/anaconda3/envs/cc-env/lib/python3.7/runpy.py", line 193, in _run_module_as_main
    "__main__", mod_spec)
  File "/Users/weitang/opt/anaconda3/envs/cc-env/lib/python3.7/runpy.py", line 85, in _run_code
    exec(code, run_globals)
  File "/Users/weitang/Documents/circuit_cutting/scalability/fake_reconstructor.py", line 97, in <module>
    reconstructed_prob = reconstructed_reorder(reconstructed_prob,complete_path_map=case_dict['complete_path_map'],smart_order=smart_order)
KeyError: 'complete_path_map'
Cut into [ 9 11] clusters
smart order: (0, 1)
Searcher took 0.424 seconds
Quantum took 4.147 seconds
Compute took 0.000 seconds
-------------------------------------------------- Reconstructor --------------------------------------------------
Existing cases: dict_keys([])
case (11, 16)
Traceback (most recent call last):
  File "/Users/weitang/opt/anaconda3/envs/cc-env/lib/python3.7/runpy.py", line 193, in _run_module_as_main
    "__main__", mod_spec)
  File "/Users/weitang/opt/anaconda3/envs/cc-env/lib/python3.7/runpy.py", line 85, in _run_code
    exec(code, run_globals)
  File "/Users/weitang/Documents/circuit_cutting/scalability/fake_reconstructor.py", line 88, in <module>
    states=range(1000))
  File "/Users/weitang/Documents/circuit_cutting/scalability/fake_reconstruct_helper_fun.py", line 26, in fake_reconstruct
    clusters_init_meas = find_inits_meas(cluster_circs, O_rho_pairs, s)
NameError: name 'cluster_circs' is not defined
Cut into [ 9 11] clusters
smart order: (0, 1)
s_0 = ('I', 'I', 'I', 'I')
